Workbook

Sheet README
A1: NEXORA CUSTOMER SOLUTIONS
A2: Customer Support & SLA Performance Analysis | Operational Portfolio Project
A5: Project Overview | B5: Analyzes 550 customer support service tickets processed between July 1, 2025, and December 31, 2025 across 4 operational departments at Nexora Customer Solutions. Evaluates SLA compliance, resolution times, backlogs, and customer satisfaction (CSAT).
A6: Target Roles | B6: Operations Analyst, Business Operations Analyst, Process Analyst, MIS Executive, Reporting Analyst.
A7: Organization Profile | B7: Nexora Customer Solutions - Enterprise Customer Care & Technical Operations Provider.
A9: Workbook Navigation
A10: 1. README | B10: Project context, scope, operational definitions, and workbook architecture.
A11: 2. RAW DATA | B11: Original transactional log containing 550 customer support records from CRM.
A12: 3. CLEAN DATA | B12: Standardized dataset with calculated metrics including Overdue flag and validation.
A13: 4. KPI ANALYSIS | B13: Master KPI executive summary table with formulas, target benchmarks, and variance analysis.
A14: 5. MONTHLY SUMMARY | B14: Monthly aggregation of ticket volumes, SLA compliance rates, average turnaround times, and CSAT.
A15: 6. DEPARTMENT SUMMARY | B15: Departmental performance breakdown across Technical Support, Billing & Invoicing, Customer Care, and Product Operations.
A16: 7. AGENT SUMMARY | B16: Individual performance scorecard for 13 support agents tracking volume, compliance, resolution speed, and CSAT.
A17: 8. DASHBOARD | B17: Visual executive dashboard featuring high-level KPI cards and 4 operational charts.
A18: 9. BUSINESS INSIGHTS | B18: Detailed qualitative and quantitative business insights with 5 core problem statements, root causes, and strategic action plans.
A20: Data Dictionary & Logic
A21: Ticket ID | B21: Unique 7-character alphanumeric ticket identifier (TCK-1001 to TCK-1550).
A22: Ticket Created Date | B22: Timestamp when customer query entered the system (YYYY-MM-DD HH:MM).
A23: Ticket Closed Date | B23: Timestamp when query resolution was validated and marked closed (Blank for open tickets).
A24: Customer ID | B24: Unique customer account reference (CUST-1000 to CUST-2500).
A25: Support Department | B25: Managing business unit: Technical Support, Billing & Invoicing, Customer Care, Product Operations.
A26: Issue Category | B26: Granular categorization of root problem (e.g., Software Bug, Payment Failure, Account Access).
A27: Priority | B27: Urgency tier: Critical (8h SLA), High (24h SLA), Medium (48h SLA), Low (72h SLA).
A28: Assigned Agent | B28: Staff member responsible for ticket resolution.
A29: Ticket Status | B29: Closed (Resolved), In Progress (Under investigation), Pending Customer (Awaiting client info).
A30: SLA Target Hours | B30: Contractual commitment window in hours based on priority level.
A31: Actual Resolution Hours | B31: Elapsed duration from creation to closure. Blank for unresolved tickets.
A32: SLA Met | B32: Yes (Actual <= SLA Target), No (Actual > SLA Target), Pending (for open tickets).
... A36: Overdue Flag | B36: Yes if current open time exceeds SLA target as of reporting cutoff (2025-12-31); No if within SLA; N/A if Closed.

Sheet RAW DATA
A1: Ticket ID | B1: Ticket Created Date | C1: Ticket Closed Date | D1: Customer ID | E1: Support Department | F1: Issue Category | G1: Priority | H1: Assigned Agent | I1: Ticket Status | J1: SLA Target Hours | K1: Actual Resolution Hours | L1: SLA Met | M1: Customer Satisfaction Score | N1: Reopened | O1: Escalated | P1: Resolution Channel
A2: TCK-1001 | B2: 2025-08-10 12:40 | C2: 2025-08-10 19:34 | D2: CUST-1863 | E2: Billing & Invoicing | F2: Invoice Discrepancy | G2: Critical | H2: David Kim | I2: Closed | J2: 8 | K2: 6.9 | L2: Yes | M2: 3 | N2: No | O2: Yes | P2: Web Portal
A3: TCK-1002 | B3: 2025-11-04 18:12 | C3: 2025-11-05 18:54 | D3: CUST-1136 | E3: Billing & Invoicing | F3: Subscription Renewal | G3: Medium | H3: Fatima Al-Mansoor | I3: Closed | J3: 48 | K3: 24.7 | L3: Yes | M3: 5 | N3: No | O3: No | P3: Phone
A4: TCK-1003 | B4: 2025-09-12 12:18 | C4: 2025-09-13 08:42 | D4: CUST-2123 | E4: Billing & Invoicing | F4: Subscription Renewal | G4: Medium | H4: Fatima Al-Mansoor | I4: Closed | J4: 48 | K4: 20.4 | L4: Yes | M4: 5 | N4: No | O4: No | P4: Live Chat
A5: TCK-1004 | B5: 2025-12-11 18:51 | C5: 2025-12-18 11:57 | D5: CUST-2011 | E5: Technical Support | F5: System Outage | G5: Low | H5: Alex Chen | I5: Closed | J5: 72 | K5: 161.1 | L5: No | M5: 2 | N5: No | O5: No | P5: Web Portal
A6: TCK-1005 | B6: 2025-10-01 19:59 | C6: 2025-10-03 14:35 | D6: CUST-1950 | E6: Customer Care | F6: Profile Update | G6: Low | H6: Anita Patel | I6: Closed | J6: 72 | K6: 42.6 | L6: Yes | M6: 5 | N6: No | O6: No | P6: Email
A7: TCK-1006 | B7: 2025-10-19 15:37 | C7: 2025-10-20 15:07 | D7: CUST-1505 | E7: Customer Care | F7: Account Access | G7: Medium | H7: Carlos Gomez | I7: Closed | J7: 48 | K7: 23.5 | L7: Yes | M7: 5 | N7: No | O7: No | P7: Web Portal
A8: TCK-1007 | B8: 2025-07-24 19:30 | C8: 2025-07-25 03:06 | D8: CUST-1508 | E8: Customer Care | F8: Profile Update | G8: Medium | H8: Carlos Gomez | I8: Closed | J8: 48 | K8: 7.6 | L8: Yes | M8: 5 | N8: No | O8: No | P8: Phone
A9: TCK-1008 | B9: 2025-11-19 09:24 | C9: 2025-11-19 15:06 | D9: CUST-2382 | E9: Customer Care | F9: Service Cancellation | G9: High | H9: Carlos Gomez | I9: Closed | J9: 24 | K9: 5.7 | L9: Yes | M9: 4 | N9: No | O9: No | P9: Email
A10: TCK-1009 | B10: 2025-09-06 19:01 | C10: 2025-09-07 02:07 | D10: CUST-1813 | E10: Product Operations | F10: Feature Request | G10: Critical | H10: Amina Yusuf | I10: Closed | J10: 8 | K10: 7.1 | L10: Yes | M10: 5 | N10: No | O10: No | P10: Email
A11: TCK-1010 | B11: 2025-10-31 19:50 | C11: 2025-11-01 19:50 | D11: CUST-2076 | E11: Technical Support | F11: Performance Lag | G11: Medium | H11: Alex Chen | I11: Closed | J11: 48 | K11: 24 | L11: Yes | M11: 4 | N11: No | O11: No | P11: Web Portal
A12: TCK-1011 | B12: 2025-10-02 14:28 | C12: 2025-10-03 05:28 | D12: CUST-1705 | E12: Billing & Invoicing | F12: Invoice Discrepancy | G12: Medium | H12: Sarah Jenkins | I12: Closed | J12: 48 | K12: 15 | L12: Yes | M12: 4 | N12: No | O12: No | P12: Email
A13: TCK-1012 | B13: 2025-10-12 15:52 | C13: 2025-10-12 18:40 | D13: CUST-1208 | E13: Customer Care | F13: Account Access | G13: Critical | H13: James Wilson | I13: Closed | J13: 8 | K13: 2.8 | L13: Yes | M13: 5 | N13: Yes | O13: No | P13: Live Chat
... A18: TCK-1017 | B18: 2025-10-21 12:01 | C18: 2025-10-21 21:49 | D18: CUST-1380 | E18: Technical Support | F18: Integration Issue | G18: Medium | H18: Alex Chen | I18: Closed | J18: 48 | K18: 9.8 | L18: Yes | M18: 4 | N18: No | O18: No | P18: Email
A19: TCK-1018 | B19: 2025-09-26 14:32 | D19: CUST-1494 | E19: Product Operations | F19: Data Sync Issue | G19: Medium | H19: Rachel Green | I19: In Progress | J19: 48 | L19: Pending | N19: No | O19: No | P19: Live Chat
A20: TCK-1019 | B20: 2025-10-18 19:52 | C20: 2025-10-19 12:34 | D20: CUST-1223 | E20: Customer Care | F20: Service Cancellation | G20: High | H20: James Wilson | I20: Closed | J20: 24 | K20: 16.7 | L20: Yes | M20: 5 | N20: No | O20: No | P20: Email
A21: TCK-1020 | B21: 2025-12-03 14:15 | C21: 2025-12-03 18:39 | D21: CUST-1017 | E21: Billing & Invoicing | F21: Subscription Renewal | G21: Critical | H21: Fatima Al-Mansoor | I21: Closed | J21: 8 | K21: 4.4 | L21: Yes | M21: 3 | N21: No | O21: No | P21: Live Chat
A22: TCK-1021 | B22: 2025-10-30 12:51 | C22: 2025-10-31 13:57 | D22: CUST-1211 | E22: Product Operations | F22: Feature Request | G22: Low | H22: Rachel Green | I22: Closed | J22: 72 | K22: 25.1 | L22: Yes | M22: 3 | N22: No | O22: No | P22: Phone
A23: TCK-1022 | B23: 2025-10-30 12:43 | C23: 2025-11-04 18:19 | D23: CUST-1675 | E23: Billing & Invoicing | F23: Invoice Discrepancy | G23: Medium | H23: David Kim | I23: Closed | J23: 48 | K23: 125.6 | L23: No | M23: 1 | N23: No | O23: No | P23: Phone
A24: TCK-1023 | B24: 2025-09-08 09:27 | C24: 2025-09-09 07:15 | D24: CUST-1581 | E24: Technical Support | F24: Software Bug | G24: High | H24: Alex Chen | I24: Closed | J24: 24 | K24: 21.8 | L24: Yes | M24: 4 | N24: No | O24: No | P24: Web Portal
A25: TCK-1024 | B25: 2025-10-04 19:48 | C25: 2025-10-07 01:42 | D25: CUST-1600 | E25: Technical Support | F25: System Outage | G25: High | H25: Alex Chen | I25: Closed | J25: 24 | K25: 53.9 | L25: No | M25: 1 | N25: No | O25: No | P25: Web Portal
A26: TCK-1025 | B26: 2025-08-26 09:29 | C26: 2025-08-27 09:53 | D26: CUST-1526 | E26: Customer Care | F26: Profile Update | G26: Medium | H26: Carlos Gomez | I26: Closed | J26: 48 | K26: 24.4 | L26: Yes | M26: 4 | N26: No | O26: No | P26: Phone
A27: TCK-1026 | B27: 2025-12-09 19:28 | C27: 2025-12-10 23:04 | D27: CUST-1712 | E27: Billing & Invoicing | F27: Subscription Renewal | G27: Medium | H27: David Kim | I27: Closed | J27: 48 | K27: 27.6 | L27: Yes | M27: 3 | N27: No | O27: No | P27: Email
A28: TCK-1027 | B28: 2025-11-18 18:32 | C28: 2025-11-20 15:26 | D28: CUST-1385 | E28: Customer Care | F28: Account Access | G28: Medium | H28: James Wilson | I28: Closed | J28: 48 | K28: 44.9 | L28: Yes | M28: 4 | N28: No | O28: No | P28: Phone
A29: TCK-1028 | B29: 2025-11-15 11:57 | C29: 2025-11-17 05:21 | D29: CUST-1344 | E29: Product Operations | F29: Configuration Error | G29: Medium | H29: Kevin Taylor | I29: Closed | J29: 48 | K29: 41.4 | L29: Yes | M29: 3 | N29: No | O29: No | P29: Web Portal
A30: TCK-1029 | B30: 2025-11-08 15:37 | C30: 2025-11-09 12:49 | D30: CUST-1616 | E30: Billing & Invoicing | F30: Payment Failure | G30: Critical | H30: Sarah Jenkins | I30: Closed | J30: 8 | K30: 21.2 | L30: No | M30: 2 | N30: No | O30: No | P30: Phone
A31: TCK-1030 | B31: 2025-11-09 14:36 | C31: 2025-11-10 04:18 | D31: CUST-1261 | E31: Billing & Invoicing | F31: Invoice Discrepancy | G31: High | H31: Fatima Al-Mansoor | I31: Closed | J31: 24 | K31: 13.7 | L31: Yes | M31: 4 | N31: No | O31: Yes | P31: Email
... A47: TCK-1046 | B47: 2025-07-11 09:58 | C47: 2025-07-11 22:46 | D47: CUST-1635 | E47: Product Operations | F47: Feature Request | G47: High | H47: Rachel Green | I47: Closed | J47: 24 | K47: 12.8 | L47: Yes | M47: 5 | N47: No | O47: No | P47: Email
A48: TCK-1047 | B48: 2025-12-19 16:04 | D48: CUST-1789 | E48: Customer Care | F48: Account Access | G48: Medium | H48: James Wilson | I48: Pending Customer | J48: 48 | L48: Pending | N48: No | O48: No | P48: Email
A49: TCK-1048 | B49: 2025-08-27 08:22 | C49: 2025-08-27 12:22 | D49: CUST-2204 | E49: Product Operations | F49: Configuration Error | G49: Critical | H49: Amina Yusuf | I49: Closed | J49: 8 | K49: 4 | L49: Yes | M49: 4 | N49: No | O49: No | P49: Live Chat
A50: TCK-1049 | B50: 2025-10-22 11:43 | C50: 2025-10-23 21:49 | D50: CUST-1491 | E50: Technical Support | F50: Integration Issue | G50: Medium | H50: Marcus Vance | I50: Closed | J50: 48 | K50: 34.1 | L50: Yes | M50: 3 | N50: No | O50: No | P50: Email
A51: TCK-1050 | B51: 2025-11-25 19:49 | C51: 2025-11-26 06:01 | D51: CUST-2110 | E51: Billing & Invoicing | F51: Payment Failure | G51: Medium | H51: Sarah Jenkins | I51: Closed | J51: 48 | K51: 10.2 | L51: Yes | M51: 5 | N51: No | O51: No | P51: Web Portal
A52: TCK-1051 | B52: 2025-07-07 18:44 | C52: 2025-07-08 06:26 | D52: CUST-1431 | E52: Customer Care | F52: Profile Update | G52: Critical | H52: Anita Patel | I52: Closed | J52: 8 | K52: 11.7 | L52: No | M52: 1 | N52: Yes | O52: No | P52: Email
A53: TCK-1052 | B53: 2025-07-30 10:09 | C53: 2025-07-31 07:39 | D53: CUST-1065 | E53: Technical Support | F53: Integration Issue | G53: Medium | H53: Marcus Vance | I53: Closed | J53: 48 | K53: 21.5 | L53: Yes | M53: 4 | N53: No | O53: No | P53: Web Portal
A54: TCK-1053 | B54: 2025-09-24 14:01 | C54: 2025-09-24 21:55 | D54: CUST-1663 | E54: Customer Care | F54: Profile Update | G54: Medium | H54: Carlos Gomez | I54: Closed | J54: 48 | K54: 7.9 | L54: Yes | M54: 4 | N54: No | O54: No | P54: Web Portal
A55: TCK-1054 | B55: 2025-11-21 08:47 | C55: 2025-11-22 19:35 | D55: CUST-2399 | E55: Technical Support | F55: Software Bug | G55: Low | H55: Marcus Vance | I55: Closed | J55: 72 | K55: 34.8 | L55: Yes | M55: 1 | N55: No | O55: No | P55: Web Portal
A56: TCK-1055 | B56: 2025-11-24 08:45 | C56: 2025-11-24 15:39 | D56: CUST-1279 | E56: Billing & Invoicing | F56: Refund Request | G56: High | H56: Sarah Jenkins | I56: Closed | J56: 24 | K56: 6.9 | L56: Yes | M56: 4 | N56: No | O56: No | P56: Phone
A57: TCK-1056 | B57: 2025-08-04 12:37 | C57: 2025-08-06 07:25 | D57: CUST-1519 | E57: Technical Support | F57: Software Bug | G57: High | H57: Priya Sharma | I57: Closed | J57: 24 | K57: 42.8 | L57: No | M57: 2 | N57: Yes | O57: No | P57: Email
A58: TCK-1057 | B58: 2025-08-23 14:01 | C58: 2025-08-23 23:25 | D58: CUST-1831 | E58: Customer Care | F58: General Inquiry | G58: Medium | H58: Carlos Gomez | I58: Closed | J58: 48 | K58: 9.4 | L58: Yes | M58: 3 | N58: No | O58: No | P58: Web Portal
A59: TCK-1058 | B59: 2025-07-07 08:15 | C59: 2025-07-09 19:33 | D59: CUST-2451 | E59: Customer Care | F59: Service Cancellation | G59: High | H59: Carlos Gomez | I59: Closed | J59: 24 | K59: 59.3 | L59: No | M59: 3 | N59: No | O59: No | P59: Web Portal
...

Sheet CLEAN DATA
A1: Ticket ID | B1: Ticket Created Date | C1: Ticket Closed Date | D1: Customer ID | E1: Support Department | F1: Issue Category | G1: Priority | H1: Assigned Agent | I1: Ticket Status | J1: SLA Target Hours | K1: Actual Resolution Hours | L1: SLA Met | M1: Customer Satisfaction Score | N1: Reopened | O1: Escalated | P1: Resolution Channel | Q1: Overdue
A2: TCK-1001 | B2: 2025-08-10 12:40 | C2: 2025-08-10 19:34 | D2: CUST-1863 | E2: Billing & Invoicing | F2: Invoice Discrepancy | G2: Critical | H2: David Kim | I2: Closed | J2: 8 | K2: 6.9 | L2: Yes | M2: 3 | N2: No | O2: Yes | P2: Web Portal | Q2: N/A
A3: TCK-1002 | B3: 2025-11-04 18:12 | C3: 2025-11-05 18:54 | D3: CUST-1136 | E3: Billing & Invoicing | F3: Subscription Renewal | G3: Medium | H3: Fatima Al-Mansoor | I3: Closed | J3: 48 | K3: 24.7 | L3: Yes | M3: 5 | N3: No | O3: No | P3: Phone | Q3: N/A
A4: TCK-1003 | B4: 2025-09-12 12:18 | C4: 2025-09-13 08:42 | D4: CUST-2123 | E4: Billing & Invoicing | F4: Subscription Renewal | G4: Medium | H4: Fatima Al-Mansoor | I4: Closed | J4: 48 | K4: 20.4 | L4: Yes | M4: 5 | N4: No | O4: No | P4: Live Chat | Q4: N/A
A5: TCK-1004 | B5: 2025-12-11 18:51 | C5: 2025-12-18 11:57 | D5: CUST-2011 | E5: Technical Support | F5: System Outage | G5: Low | H5: Alex Chen | I5: Closed | J5: 72 | K5: 161.1 | L5: No | M5: 2 | N5: No | O5: No | P5: Web Portal | Q5: N/A
A6: TCK-1005 | B6: 2025-10-01 19:59 | C6: 2025-10-03 14:35 | D6: CUST-1950 | E6: Customer Care | F6: Profile Update | G6: Low | H6: Anita Patel | I6: Closed | J6: 72 | K6: 42.6 | L6: Yes | M6: 5 | N6: No | O6: No | P6: Email | Q6: N/A
A7: TCK-1006 | B7: 2025-10-19 15:37 | C7: 2025-10-20 15:07 | D7: CUST-1505 | E7: Customer Care | F7: Account Access | G7: Medium | H7: Carlos Gomez | I7: Closed | J7: 48 | K7: 23.5 | L7: Yes | M7: 5 | N7: No | O7: No | P7: Web Portal | Q7: N/A
A8: TCK-1007 | B8: 2025-07-24 19:30 | C8: 2025-07-25 03:06 | D8: CUST-1508 | E8: Customer Care | F8: Profile Update | G8: Medium | H8: Carlos Gomez | I8: Closed | J8: 48 | K8: 7.6 | L8: Yes | M8: 5 | N8: No | O8: No | P8: Phone | Q8: N/A
A9: TCK-1008 | B9: 2025-11-19 09:24 | C9: 2025-11-19 15:06 | D9: CUST-2382 | E9: Customer Care | F9: Service Cancellation | G9: High | H9: Carlos Gomez | I9: Closed | J9: 24 | K9: 5.7 | L9: Yes | M9: 4 | N9: No | O9: No | P9: Email | Q9: N/A
A10: TCK-1009 | B10: 2025-09-06 19:01 | C10: 2025-09-07 02:07 | D10: CUST-1813 | E10: Product Operations | F10: Feature Request | G10: Critical | H10: Amina Yusuf | I10: Closed | J10: 8 | K10: 7.1 | L10: Yes | M10: 5 | N10: No | O10: No | P10: Email | Q10: N/A
A11: TCK-1010 | B11: 2025-10-31 19:50 | C11: 2025-11-01 19:50 | D11: CUST-2076 | E11: Technical Support | F11: Performance Lag | G11: Medium | H11: Alex Chen | I11: Closed | J11: 48 | K11: 24 | L11: Yes | M11: 4 | N11: No | O11: No | P11: Web Portal | Q11: N/A
A12: TCK-1011 | B12: 2025-10-02 14:28 | C12: 2025-10-03 05:28 | D12: CUST-1705 | E12: Billing & Invoicing | F12: Invoice Discrepancy | G12: Medium | H12: Sarah Jenkins | I12: Closed | J12: 48 | K12: 15 | L12: Yes | M12: 4 | N12: No | O12: No | P12: Email | Q12: N/A
A13: TCK-1012 | B13: 2025-10-12 15:52 | C13: 2025-10-12 18:40 | D13: CUST-1208 | E13: Customer Care | F13: Account Access | G13: Critical | H13: James Wilson | I13: Closed | J13: 8 | K13: 2.8 | L13: Yes | M13: 5 | N13: Yes | O13: No | P13: Live Chat | Q13: N/A
... A18: TCK-1017 | B18: 2025-10-21 12:01 | C18: 2025-10-21 21:49 | D18: CUST-1380 | E18: Technical Support | F18: Integration Issue | G18: Medium | H18: Alex Chen | I18: Closed | J18: 48 | K18: 9.8 | L18: Yes | M18: 4 | N18: No | O18: No | P18: Email | Q18: N/A
A19: TCK-1018 | B19: 2025-09-26 14:32 | D19: CUST-1494 | E19: Product Operations | F19: Data Sync Issue | G19: Medium | H19: Rachel Green | I19: In Progress | J19: 48 | L19: Pending | N19: No | O19: No | P19: Live Chat | Q19: Yes
A20: TCK-1019 | B20: 2025-10-18 19:52 | C20: 2025-10-19 12:34 | D20: CUST-1223 | E20: Customer Care | F20: Service Cancellation | G20: High | H20: James Wilson | I20: Closed | J20: 24 | K20: 16.7 | L20: Yes | M20: 5 | N20: No | O20: No | P20: Email | Q20: N/A
A21: TCK-1020 | B21: 2025-12-03 14:15 | C21: 2025-12-03 18:39 | D21: CUST-1017 | E21: Billing & Invoicing | F21: Subscription Renewal | G21: Critical | H21: Fatima Al-Mansoor | I21: Closed | J21: 8 | K21: 4.4 | L21: Yes | M21: 3 | N21: No | O21: No | P21: Live Chat | Q21: N/A
A22: TCK-1021 | B22: 2025-10-30 12:51 | C22: 2025-10-31 13:57 | D22: CUST-1211 | E22: Product Operations | F22: Feature Request | G22: Low | H22: Rachel Green | I22: Closed | J22: 72 | K22: 25.1 | L22: Yes | M22: 3 | N22: No | O22: No | P22: Phone | Q22: N/A
A23: TCK-1022 | B23: 2025-10-30 12:43 | C23: 2025-11-04 18:19 | D23: CUST-1675 | E23: Billing & Invoicing | F23: Invoice Discrepancy | G23: Medium | H23: David Kim | I23: Closed | J23: 48 | K23: 125.6 | L23: No | M23: 1 | N23: No | O23: No | P23: Phone | Q23: N/A
A24: TCK-1023 | B24: 2025-09-08 09:27 | C24: 2025-09-09 07:15 | D24: CUST-1581 | E24: Technical Support | F24: Software Bug | G24: High | H24: Alex Chen | I24: Closed | J24: 24 | K24: 21.8 | L24: Yes | M24: 4 | N24: No | O24: No | P24: Web Portal | Q24: N/A
A25: TCK-1024 | B25: 2025-10-04 19:48 | C25: 2025-10-07 01:42 | D25: CUST-1600 | E25: Technical Support | F25: System Outage | G25: High | H25: Alex Chen | I25: Closed | J25: 24 | K25: 53.9 | L25: No | M25: 1 | N25: No | O25: No | P25: Web Portal | Q25: N/A
A26: TCK-1025 | B26: 2025-08-26 09:29 | C26: 2025-08-27 09:53 | D26: CUST-1526 | E26: Customer Care | F26: Profile Update | G26: Medium | H26: Carlos Gomez | I26: Closed | J26: 48 | K26: 24.4 | L26: Yes | M26: 4 | N26: No | O26: No | P26: Phone | Q26: N/A
A27: TCK-1026 | B27: 2025-12-09 19:28 | C27: 2025-12-10 23:04 | D27: CUST-1712 | E27: Billing & Invoicing | F27: Subscription Renewal | G27: Medium | H27: David Kim | I27: Closed | J27: 48 | K27: 27.6 | L27: Yes | M27: 3 | N27: No | O27: No | P27: Email | Q27: N/A
A28: TCK-1027 | B28: 2025-11-18 18:32 | C28: 2025-11-20 15:26 | D28: CUST-1385 | E28: Customer Care | F28: Account Access | G28: Medium | H28: James Wilson | I28: Closed | J28: 48 | K28: 44.9 | L28: Yes | M28: 4 | N28: No | O28: No | P28: Phone | Q28: N/A
A29: TCK-1028 | B29: 2025-11-15 11:57 | C29: 2025-11-17 05:21 | D29: CUST-1344 | E29: Product Operations | F29: Configuration Error | G29: Medium | H29: Kevin Taylor | I29: Closed | J29: 48 | K29: 41.4 | L29: Yes | M29: 3 | N29: No | O29: No | P29: Web Portal | Q29: N/A
A30: TCK-1029 | B30: 2025-11-08 15:37 | C30: 2025-11-09 12:49 | D30: CUST-1616 | E30: Billing & Invoicing | F30: Payment Failure | G30: Critical | H30: Sarah Jenkins | I30: Closed | J30: 8 | K30: 21.2 | L30: No | M30: 2 | N30: No | O30: No | P30: Phone | Q30: N/A
A31: TCK-1030 | B31: 2025-11-09 14:36 | C31: 2025-11-10 04:18 | D31: CUST-1261 | E31: Billing & Invoicing | F31: Invoice Discrepancy | G31: High | H31: Fatima Al-Mansoor | I31: Closed | J31: 24 | K31: 13.7 | L31: Yes | M31: 4 | N31: No | O31: Yes | P31: Email | Q31: N/A
... A47: TCK-1046 | B47: 2025-07-11 09:58 | C47: 2025-07-11 22:46 | D47: CUST-1635 | E47: Product Operations | F47: Feature Request | G47: High | H47: Rachel Green | I47: Closed | J47: 24 | K47: 12.8 | L47: Yes | M47: 5 | N47: No | O47: No | P47: Email | Q47: N/A
A48: TCK-1047 | B48: 2025-12-19 16:04 | D48: CUST-1789 | E48: Customer Care | F48: Account Access | G48: Medium | H48: James Wilson | I48: Pending Customer | J48: 48 | L48: Pending | N48: No | O48: No | P48: Email | Q48: Yes
A49: TCK-1048 | B49: 2025-08-27 08:22 | C49: 2025-08-27 12:22 | D49: CUST-2204 | E49: Product Operations | F49: Configuration Error | G49: Critical | H49: Amina Yusuf | I49: Closed | J49: 8 | K49: 4 | L49: Yes | M49: 4 | N49: No | O49: No | P49: Live Chat | Q49: N/A
A50: TCK-1049 | B50: 2025-10-22 11:43 | C50: 2025-10-23 21:49 | D50: CUST-1491 | E50: Technical Support | F50: Integration Issue | G50: Medium | H50: Marcus Vance | I50: Closed | J50: 48 | K50: 34.1 | L50: Yes | M50: 3 | N50: No | O50: No | P50: Email | Q50: N/A
A51: TCK-1050 | B51: 2025-11-25 19:49 | C51: 2025-11-26 06:01 | D51: CUST-2110 | E51: Billing & Invoicing | F51: Payment Failure | G51: Medium | H51: Sarah Jenkins | I51: Closed | J51: 48 | K51: 10.2 | L51: Yes | M51: 5 | N51: No | O51: No | P51: Web Portal | Q51: N/A
A52: TCK-1051 | B52: 2025-07-07 18:44 | C52: 2025-07-08 06:26 | D52: CUST-1431 | E52: Customer Care | F52: Profile Update | G52: Critical | H52: Anita Patel | I52: Closed | J52: 8 | K52: 11.7 | L52: No | M52: 1 | N52: Yes | O52: No | P52: Email | Q52: N/A
A53: TCK-1052 | B53: 2025-07-30 10:09 | C53: 2025-07-31 07:39 | D53: CUST-1065 | E53: Technical Support | F53: Integration Issue | G53: Medium | H53: Marcus Vance | I53: Closed | J53: 48 | K53: 21.5 | L53: Yes | M53: 4 | N53: No | O53: No | P53: Web Portal | Q53: N/A
A54: TCK-1053 | B54: 2025-09-24 14:01 | C54: 2025-09-24 21:55 | D54: CUST-1663 | E54: Customer Care | F54: Profile Update | G54: Medium | H54: Carlos Gomez | I54: Closed | J54: 48 | K54: 7.9 | L54: Yes | M54: 4 | N54: No | O54: No | P54: Web Portal | Q54: N/A
A55: TCK-1054 | B55: 2025-11-21 08:47 | C55: 2025-11-22 19:35 | D55: CUST-2399 | E55: Technical Support | F55: Software Bug | G55: Low | H55: Marcus Vance | I55: Closed | J55: 72 | K55: 34.8 | L55: Yes | M55: 1 | N55: No | O55: No | P55: Web Portal | Q55: N/A
A56: TCK-1055 | B56: 2025-11-24 08:45 | C56: 2025-11-24 15:39 | D56: CUST-1279 | E56: Billing & Invoicing | F56: Refund Request | G56: High | H56: Sarah Jenkins | I56: Closed | J56: 24 | K56: 6.9 | L56: Yes | M56: 4 | N56: No | O56: No | P56: Phone | Q56: N/A
A57: TCK-1056 | B57: 2025-08-04 12:37 | C57: 2025-08-06 07:25 | D57: CUST-1519 | E57: Technical Support | F57: Software Bug | G57: High | H57: Priya Sharma | I57: Closed | J57: 24 | K57: 42.8 | L57: No | M57: 2 | N57: Yes | O57: No | P57: Email | Q57: N/A
A58: TCK-1057 | B58: 2025-08-23 14:01 | C58: 2025-08-23 23:25 | D58: CUST-1831 | E58: Customer Care | F58: General Inquiry | G58: Medium | H58: Carlos Gomez | I58: Closed | J58: 48 | K58: 9.4 | L58: Yes | M58: 3 | N58: No | O58: No | P58: Web Portal | Q58: N/A
A59: TCK-1058 | B59: 2025-07-07 08:15 | C59: 2025-07-09 19:33 | D59: CUST-2451 | E59: Customer Care | F59: Service Cancellation | G59: High | H59: Carlos Gomez | I59: Closed | J59: 24 | K59: 59.3 | L59: No | M59: 3 | N59: No | O59: No | P59: Web Portal | Q59: N/A
...

Sheet KPI ANALYSIS
A1: NEXORA CUSTOMER SOLUTIONS - MASTER KPI PERFORMANCE SCORECARD
A2: Reporting Period: July 1, 2025 - December 31, 2025 | Total Records Analyzed: 550
A4: KPI Metric | B4: Formula / Excel Definition | C4: Calculated Value | D4: Operational Benchmark | E4: Status / Variance | F4: Business Impact & Interpretation
A5: Total Tickets Received | B5: =COUNTA('CLEAN DATA'!A2:A551) -> 550 | C5: 550 | D5: N/A (Volume) | E5: Baseline Volume | F5: Total support inquiry load ingested across all channels.
A6: Total Resolved Tickets | B6: =COUNTIF('CLEAN DATA'!I2:I551, "Closed") -> 501 | C6: 501 | D6: >= 90.0% | E6: 91.1% Resolved (Healthy) | F6: Queries successfully closed and validated by support.
A7: Total Open Tickets | B7: =COUNTIF('CLEAN DATA'!I2:I551, "<>Closed") -> 49 | C7: 49 | D7: < 10.0% | E7: 8.9% Open Backlog | F7: Active cases currently under investigation or awaiting customer reply.
A8: Overdue Open Tickets | B8: =COUNTIF('CLEAN DATA'!Q2:Q551, "Yes") -> 47 | C8: 47 | D8: 0 Tickets | E8: 47 Overdue (Action Req.) | F8: Active tickets whose elapsed time exceeds SLA resolution target.
A9: Ticket Resolution Rate | B9: =C6/C5 -> 0.91090909 | C9: 0.91090909 | D9: >= 90.0% | E9: +1.1% vs Target | F9: Proportion of total tickets resolved within the operating period.
A10: SLA Compliance Rate | B10: =COUNTIF('CLEAN DATA'!L2:L551, "Yes")/C6 -> 0.77045908 | C10: 0.77045908 | D10: >= 85.0% | E10: -8.0% vs Target | F10: Percentage of closed tickets resolved within agreed SLA hours.
A11: Average Resolution Time (Hours) | B11: =AVERAGE('CLEAN DATA'!K2:K551) -> 34.358483 | C11: 34.4 | D11: <= 32.0 Hours | E11: +2.4 Hours vs Target | F11: Mean elapsed business turnaround time per closed ticket.
A12: Average Customer Satisfaction (CSAT) | B12: =AVERAGE('CLEAN DATA'!M2:M551) -> 3.5409182 | C12: 3.54 | D12: >= 4.00 / 5.00 | E12: -0.46 Deficit | F12: Overall client satisfaction score on 1-5 post-resolution rating.
A13: Ticket Escalation Rate | B13: =COUNTIF('CLEAN DATA'!O2:O551, "Yes")/C5 -> 0.098181818 | C13: 0.098181818 | D13: <= 8.0% | E13: Above Target — Improvement Required | F13: Percentage of inquiries escalated to senior tier engineers/leads.
A14: Ticket Reopening Rate | B14: =COUNTIF('CLEAN DATA'!N2:N551, "Yes")/C5 -> 0.10181818 | C14: 0.10181818 | D14: <= 6.0% | E14: +3.6% Over Limit | F14: Percentage of resolved tickets reopened due to recurring issues.

Sheet MONTHLY SUMMARY
A1: NEXORA CUSTOMER SOLUTIONS - MONTHLY OPERATIONAL TRENDS
A2: Historical Support Volume & Efficiency Trajectory (July - December 2025)
A4: Month | B4: Total Inflow | C4: Resolved Tickets | D4: Open Tickets | E4: Resolution Rate | F4: SLA Met | G4: SLA Compliance % | H4: Avg Resolution (Hrs) | I4: Avg CSAT | J4: Escalated | K4: Reopened
A5: 2025-07 | B5: 95 | C5: 90 | D5: 5 | E5: 0.947 | F5: 67 | G5: 0.744 | H5: 35.7 | I5: 3.43 | J5: 11 | K5: 10
A6: 2025-08 | B6: 93 | C6: 86 | D6: 7 | E6: 0.925 | F6: 68 | G6: 0.791 | H6: 34.9 | I6: 3.51 | J6: 9 | K6: 8
A7: 2025-09 | B7: 90 | C7: 85 | D7: 5 | E7: 0.944 | F7: 68 | G7: 0.8 | H7: 30.8 | I7: 3.69 | J7: 9 | K7: 8
A8: 2025-10 | B8: 89 | C8: 78 | D8: 11 | E8: 0.876 | F8: 63 | G8: 0.808 | H8: 34.3 | I8: 3.6 | J8: 5 | K8: 11
A9: 2025-11 | B9: 104 | C9: 102 | D9: 2 | E9: 0.981 | F9: 77 | G9: 0.755 | H9: 28.9 | I9: 3.57 | J9: 10 | K9: 9
A10: 2025-12 | B10: 79 | C10: 60 | D10: 19 | E10: 0.759 | F10: 43 | G10: 0.717 | H10: 45.9 | I10: 3.4 | J10: 10 | K10: 10
A11: Total / Period Avg | B11: =SUM(B5:B10) -> 550 | C11: =SUM(C5:C10) -> 501 | D11: =SUM(D5:D10) -> 49 | E11: =C11/B11 -> 0.91090909 | F11: =SUM(F5:F10) -> 386 | G11: =F11/C11 -> 0.77045908 | H11: =AVERAGE(H5:H10) -> 35.083333 | I11: =AVERAGE(I5:I10) -> 3.5333333 | J11: =SUM(J5:J10) -> 54 | K11: =SUM(K5:K10) -> 56

Sheet DEPARTMENT SUMMARY
A1: NEXORA CUSTOMER SOLUTIONS - DEPARTMENTAL PERFORMANCE BREAKDOWN
A2: Cross-Departmental SLA Compliance, Backlog & Service Quality Metrics
A4: Support Department | B4: Total Tickets | C4: Resolved | D4: Open Backlog | E4: Resolution % | F4: SLA Met | G4: SLA Compliance % | H4: Avg Resolution (Hrs) | I4: Avg CSAT | J4: Escalations | K4: Reopened
A5: Billing & Invoicing | B5: 127 | C5: 112 | D5: 15 | E5: 0.882 | F5: 85 | G5: 0.759 | H5: 32.6 | I5: 3.68 | J5: 12 | K5: 13
A6: Customer Care | B6: 122 | C6: 110 | D6: 12 | E6: 0.902 | F6: 81 | G6: 0.736 | H6: 35.2 | I6: 3.55 | J6: 13 | K6: 13
A7: Product Operations | B7: 114 | C7: 103 | D7: 11 | E7: 0.904 | F7: 86 | G7: 0.835 | H7: 28.4 | I7: 3.55 | J7: 9 | K7: 12
A8: Technical Support | B8: 187 | C8: 176 | D8: 11 | E8: 0.941 | F8: 134 | G8: 0.761 | H8: 38.4 | I8: 3.44 | J8: 20 | K8: 18
A9: Company Total / Avg | B9: =SUM(B5:B8) -> 550 | C9: =SUM(C5:C8) -> 501 | D9: =SUM(D5:D8) -> 49 | E9: =C9/B9 -> 0.91090909 | F9: =SUM(F5:F8) -> 386 | G9: =F9/C9 -> 0.77045908 | H9: =AVERAGE(H5:H8) -> 33.65 | I9: =AVERAGE(I5:I8) -> 3.555 | J9: =SUM(J5:J8) -> 54 | K9: =SUM(K5:K8) -> 56

Sheet AGENT SUMMARY
A1: NEXORA CUSTOMER SOLUTIONS - SUPPORT AGENT PERFORMANCE SCORECARD
A2: Individual Agent Workload, SLA Compliance, Speed & Customer CSAT Ratings
A4: Assigned Agent | B4: Department | C4: Assigned Tickets | D4: Closed Tickets | E4: Open Tickets | F4: SLA Met | G4: SLA Compliance % | H4: Avg Res Time (Hrs) | I4: Avg CSAT | J4: Performance Status
A5: Alex Chen | B5: Technical Support | C5: 49 | D5: 47 | E5: 2 | F5: 34 | G5: 0.723 | H5: 39.7 | I5: 3.45 | J5: Needs Coaching
A6: Amina Yusuf | B6: Product Operations | C6: 43 | D6: 40 | E6: 3 | F6: 34 | G6: 0.85 | H6: 27.1 | I6: 3.75 | J6: Exceeds Expectations
A7: Anita Patel | B7: Customer Care | C7: 44 | D7: 39 | E7: 5 | F7: 31 | G7: 0.795 | H7: 34.3 | I7: 3.72 | J7: Meets Expectations
A8: Carlos Gomez | B8: Customer Care | C8: 44 | D8: 40 | E8: 4 | F8: 26 | G8: 0.65 | H8: 34.1 | I8: 3.28 | J8: Needs Coaching
A9: David Kim | B9: Billing & Invoicing | C9: 33 | D9: 32 | E9: 1 | F9: 25 | G9: 0.781 | H9: 30.8 | I9: 3.47 | J9: Meets Expectations
A10: Elena Rostova | B10: Technical Support | C10: 47 | D10: 47 | E10: 0 | F10: 39 | G10: 0.83 | H10: 33.8 | I10: 3.47 | J10: Meets Expectations
A11: Fatima Al-Mansoor | B11: Billing & Invoicing | C11: 54 | D11: 47 | E11: 7 | F11: 35 | G11: 0.745 | H11: 31.7 | I11: 3.64 | J11: Needs Coaching
A12: James Wilson | B12: Customer Care | C12: 34 | D12: 31 | E12: 3 | F12: 24 | G12: 0.774 | H12: 37.8 | I12: 3.71 | J12: Meets Expectations
A13: Kevin Taylor | B13: Product Operations | C13: 33 | D13: 29 | E13: 4 | F13: 22 | G13: 0.759 | H13: 31.8 | I13: 3.31 | J13: Needs Coaching
A14: Marcus Vance | B14: Technical Support | C14: 52 | D14: 51 | E14: 1 | F14: 43 | G14: 0.843 | H14: 35.6 | I14: 3.65 | J14: Exceeds Expectations
A15: Priya Sharma | B15: Technical Support | C15: 39 | D15: 31 | E15: 8 | F15: 18 | G15: 0.581 | H15: 47.9 | I15: 3.03 | J15: Needs Coaching
A16: Rachel Green | B16: Product Operations | C16: 38 | D16: 34 | E16: 4 | F16: 30 | G16: 0.882 | H16: 27.2 | I16: 3.53 | J16: Exceeds Expectations
A17: Sarah Jenkins | B17: Billing & Invoicing | C17: 40 | D17: 33 | E17: 7 | F17: 25 | G17: 0.758 | H17: 35.8 | I17: 3.94 | J17: Meets Expectations

Sheet DASHBOARD
A1: NEXORA CUSTOMER SOLUTIONS - EXECUTIVE SUPPORT DASHBOARD | U1: Category Volume Helper
A2: Operational Performance, SLA Adherence & Customer Experience Overview (H2 2025) | U2: Category | V2: Volume
U3: System Outage | V3: 56
B4: TOTAL TICKETS | E4: RESOLVED TICKETS | H4: OPEN BACKLOG | K4: SLA COMPLIANCE | N4: AVG RESOLUTION TIME | Q4: AVG CSAT SCORE | U4: Software Bug | V4: 51
B5: 550 | E5: 501 | H5: 49 | K5: 0.77045908 | N5: 34.4 hrs | Q5: 3.54 / 5.0 | U5: Integration Issue | V5: 46
B6: Total support volume | E6: 91.1% overall closure | H6: 47 overdue (> SLA) | K6: Target: >= 85.0% | N6: Benchmark: <= 32.0 hrs | Q6: Benchmark: >= 4.00 | U6: Subscription Renewal | V6: 42
U7: Profile Update | V7: 41
U8: Configuration Error | V8: 35
U9: Product Defect | V9: 35
U10: Performance Lag | V10: 34
U11: Invoice Discrepancy | V11: 30
U12: Payment Failure | V12: 30
U13: General Inquiry | V13: 28
U14: Service Cancellation | V14: 27
U15: Account Access | V15: 26
U16: Feature Request | V16: 25
U17: Refund Request | V17: 25
U18: Data Sync Issue | V18: 19

Sheet BUSINESS INSIGHTS
A1: NEXORA CUSTOMER SOLUTIONS - STRATEGIC BUSINESS INSIGHTS & ACTION PLANS
A2: Actionable Findings Derived from 550 Support Incidents | Recommendations for Operations Leadership
A4: Insight # | B4: Problem / Observation Area | C4: What the Data Shows (Quantitative Evidence) | D4: Operational Metric / Calculation | E4: Business Impact & Root Cause | F4: Recommended Strategic Action Plan
A5: Insight 1 | B5: Technical Support Bottleneck & CSAT Erosion | C5: Technical Support handles the largest ticket volume (187 of 550 tickets, 34.0%), but experiences high resolution times and subdued CSAT compared to company standards. | D5: Volume: 187 | SLA Met: 134 | Avg Resolution: 38.4 hrs | Avg CSAT: 3.44 | E5: Technical complexity and tier-1 skill mismatches result in prolonged troubleshooting, high customer friction, and negative CSAT drag across the enterprise. | F5: Implement Tier-1 technical diagnostic runbooks, create dedicated routing for 'Software Bug' and 'System Outage' to senior engineers, and introduce asynchronous diagnostic logging.
A6: Insight 2 | B6: Severe Open Ticket Aging & Overdue SLA Risk | C6: Out of 49 currently open tickets, 47 tickets (95.9% of active backlog) have exceeded their SLA resolution threshold, creating compliance exposure. | D6: Active Backlog: 49 tickets | Overdue Tickets: 47 (95.9% of backlog, 8.5% of total volume). | E6: Stale tickets languishing in 'Pending Customer' and 'In Progress' states inflate churn risk among high-value enterprise accounts and indicate poor queue governance. | F6: Establish automated aging alerts at 50% and 75% SLA consumption, mandate daily backlog standups, and deploy an automated 'auto-close after 5 days no response' rule for pending customer tickets.
A7: Insight 3 | B7: Agent Workload & Performance Disparity | C7: A noticeable performance variance exists across the support team: Amina Yusuf achieved superior SLA compliance and high CSAT with swift turnaround, whereas lagging agents experienced lower compliance and longer queues. | D7: Top performers achieve >85% SLA compliance and >3.70 CSAT, whereas lower-tier performers drop below 72% compliance with >40h turnaround. | E7: Inconsistent adherence to best-practice macros and uneven ticket distribution lead to agent burnout, delayed first-contact resolution, and customer dissatisfaction. | F7: Conduct peer shadowing between top performers and lagging agents, rebalance automated routing quotas in the CRM, and establish weekly 1-on-1 operational coaching sessions.
A8: Insight 4 | B8: Impact of Resolution Breaches on Customer Retention & CSAT | C8: SLA compliance is the primary driver of customer sentiment: Tickets that met SLA achieved an average CSAT of 3.98 with only a 4.4% escalation rate, whereas SLA-breached tickets plunged to 2.08 CSAT with a 26.1% escalation rate. | D8: Met SLA CSAT: 3.98 vs Breached SLA CSAT: 2.08 (Delta: -1.90 pts) | Escalation Rate: 4.4% vs 26.1%. | E8: SLA breaches trigger a compounding cascade of escalations and reopened tickets, consuming disproportionate senior engineer capacity and tripling cost per ticket. | F8: Institute early-warning trigger alarms at 60% SLA elapsed time to fast-track interventions before deadlines breach, and mandate warm handoffs for escalations.
A9: Insight 5 | B9: Billing & Invoicing Escalation & Ingestion Inefficiencies | C9: Billing & Invoicing accounted for 127 tickets and significant escalations, driven by 'Payment Failure' and 'Refund Request'. | D9: Billing Volume: 127 | Escalations: 12 | SLA Compliance: 75.9%. | E9: Lack of customer-facing self-service tools for billing disputes and gateway retry logic forces routine transactional queries into high-touch manual agent queues. | F9: Deploy a self-service customer portal for instant invoice downloads and dispute logging, integrate automated payment gateway retry notifications, and empower billing tier-1 with standard refund approval limits.
